Workbook

Sheet README
A1: EnergiaPY.live — Base Maestra V5
A2: V5 consolidates the V4 historical/economic base with latest verified operational, customer, hydrology, climate, macro, household and grid-quality baselines. No synthetic data.
A4: Version | B4: v3 / 11-09-2026
A5: Principio | B5: Nunca completar silenciosamente datos faltantes. Dato oficial, contractual, periodistico y derivado se etiquetan por separado.
A6: Measurements | B6: 1,458 observaciones totales; 1,340 canónicas para métricas.
A7: Prices | B7: 368 referencias/tarifas/precios + tarifas residenciales vigentes y reglas de tarifa social.
A8: Economic transactions | B8: 76 pagos/compensaciones/royalties.
A9: Infrastructure | B9: 149 observaciones de red/capacidad.
A10: Earliest physical history | B10: Acaray/interconexion: 1968/1969 marker; Itaipu generation: 1984; Yacyreta generation: 1994; ANDE billed series: 1983.
A11: Economic history | B11: Itaipu royalties: 1989; ANDE tariff averages: 1990; cession detail loaded: 2013 onward; Yacyreta legal framework from treaty/notes reversales.
A12: Queued | B12: ONS Itaipu hourly, ONS international exchanges, CAMMESA API/files, ANDE/INE GIS and post-2012 EBY monthly backfill.
A13: Canonical rule | B13: For a logical duplicate, only canonical_flag=1 enters metrics. Highest revision_priority wins; alternates remain for audit.
A14: Economic rule | B14: Cession compensation != market sale != tariff != royalty. Never combine them without explicit metric definition.
A15: Recommended production tables | B15: measurements, prices, economic_terms, economic_transactions, infrastructure, source_documents, quality_issues, import_queue, assets, sources.
... A22: Derived averages | B22: Equivalent MW from GWh/time are derived reference averages, not instantaneous measured MW.

Sheet Coverage
A1: dataset | B1: source_start | C1: source_end | D1: loaded_start | E1: loaded_end | F1: status | G1: notes
A2: ANDE billed market | B2: 1983 | C2: 2018 | D2: 1983 | E2: 2018 | F2: loaded/revised | G2: Billed by sector + export; later categories require continuation from newer documents
A3: ANDE SIN gross consumption/demand | B3: 2003 | C3: 2026 | D3: 2003 | E3: 2026-05 + events | F3: loaded | G3: Annual through 2025; monthly Jan-May 2026 currently in seed
A4: ANDE tariff averages | B4: 1990 | C4: 2024 | D4: 1990 | E4: 2024 + current tariff bands | F4: loaded | G4: Tarifa media oficial 1990-2024; Pliego 21 residencial/social vigente cargado. 2025 anual pendiente; proxy provisional en summary.
A5: ANDE transmission/distribution | B5: 2003 | C5: 2023 | D5: 2003 | E5: 2023 | F5: loaded | G5: GIS geometry of individual lines/substations pending
A6: Acaray interconnection/export history | B6: 1969 | C6: current | D6: 1969 contract marker | E6: 2025 export totals | F6: partial | G6: Detailed hourly plant output not public in seed
A7: Itaipu generation | B7: 1984 | C7: current | D7: 1984 | E7: 2002 + 2018-20 supply + 2024-25 generation | F7: partial | G7: ONS hourly backfill will fill major gap
A8: Itaipu royalties | B8: 1989 | C8: current | D8: 1989 | E8: 2026-08 partial | F8: loaded | G8: Annual cash series + current YTD
A9: Itaipu cession compensation | B9: 2013 | C9: current | D9: 2013 | E9: 2026-08 partial | F9: partial | G9: 2019 exact cash cession omitted until source-specific verification
A10: Yacyreta generation/destination | B10: 1994 | C10: current | D10: 1994-08 | E10: 2012-06 + 2020 | F10: partial | G10: Need later monthly backfill/API/public reports
A11: Yacyreta economic/legal | B11: 1973 | C11: current | D11: 1973 legal | E11: 2025 contract + 2024 payments | F11: partial | G11: Need systematic annual compensation/royalties series
A12: ONS Itaipu hourly | B12: dataset availability | C12: current | F12: queued | G12: Official bulk dataset identified; load on server
A13: ONS international exchange | B13: dataset availability | C13: current | F13: queued | G13: Official bulk dataset identified; load on server
A14: CAMMESA SADI/flows | B14: historical/current | C14: current | F14: queued | G14: API + monthly Variables Relevantes identified
A15: BCP FX / IPC for tariff normalization | B15: 1950 IPC / FX historical | C15: current | D15: 1990 | E15: 2025 annual + 2026 current snapshots | F15: loaded_provisional | G15: WDI/IMF annual backfill 1990-2025 + BCP 2026 current. Raw BCP historical reconciliation remains required.
A16: Tariff normalization real/USD | B16: 1990 | C16: 2025 | D16: 1990 | E16: 2025 | F16: loaded | G16: All canonical ANDE PYG/kWh tariffs converted to real-2025 PYG/kWh and USD/MWh using annual macro layer.
A17: ANDE customer categories 2025 | B17: 2025 | C17: 2025 | D17: 2025 | E17: 2025 | F17: loaded | G17: Billed kWh + user counts + derived kWh/user and shares.
A18: ANDE losses and continuity | B18: 2015/current | C18: current | D18: 2024/25 | E18: 2025 + targets | F18: loaded/current-baseline | G18: National loss + Metropolitan DEP/FEP; deeper regional series still desirable.
A19: Itaipu current-year operations | B19: 2026 | C19: current | D19: 2026-01 | E19: 2026-08 | F19: loaded | G19: Jan-Aug production/supply and availability plus derived equivalent average power.
A20: Yacyreta current hydrology/power | B20: current | C20: current | D20: 2026-09-10 | E20: 2026-09-11 | F20: loaded/current-baseline | G20: Current operational/hydrological snapshot; exact homepage power timestamp unavailable.
A21: BCP IMAEP contextual features | B21: historical | C21: current | D21: 2026-01 | E21: 2026-06 | F21: loaded-current | G21: Latest verified numeric report June 2026; historical monthly backfill can follow.
A22: INE household income | B22: EPHC historical | C22: 2025 | D22: 2025 | E22: 2025 | F22: loaded-baseline | G22: 2025 aggregate income and quintiles; microdata not yet fully backfilled.
A23: INE household/equipment census | B23: 2002/2012/2022 | C23: 2022 | D23: 2022 | E23: 2022 | F23: loaded-baseline | G23: Electricity access and energy-relevant appliance penetration.
A24: NOAA ENSO/RONI outlook | B24: 1950/current | C24: current | D24: 2026-09 issue | E24: 9 seasons | F24: loaded-current | G24: September 2026 outlook; full historical ONI/RONI backfill remains optional/high value.
A25: DMH automatic stations | B25: current | C25: current | D25: 2026-09-10 | E25: 2026-09-10 snapshot | F25: partial-current | G25: Orientative web data; production collector should store full 10-min series.
A26: Distributed generation | B26: 2026 | C26: current | D26: regulatory | E26: quantitative pending | F26: framework-loaded | G26: Legal framework active; public installed MW/user series not found.

Sheet Sources
A1: code | B1: name | C1: country | D1: authority_class | E1: base_url | F1: scope
A2: ANDE | B2: Administracion Nacional de Electricidad | C2: PY | D2: OFFICIAL_PRIMARY | E2: https://www.ande.gov.py/ | F2: SIN Paraguay, Acaray, balance, demanda, consumo, perdidas, tarifas, red, exportaciones ANDE
A3: ITAIPU | B3: Itaipu Binacional | C3: PY/BR | D3: OFFICIAL_PRIMARY | E3: https://www.itaipu.gov.py/ | F3: Generacion Itaipu, suministro, Anexo C, royalties, cesion, facturacion
A4: EBY | B4: Entidad Binacional Yacyreta | C4: PY/AR | D4: OFFICIAL_PRIMARY | E4: https://www.eby.gov.py/ | F4: Generacion Yacyreta, entregas SINP/SADI, acuerdos operativos, cesion
A5: ONS | B5: Operador Nacional do Sistema Eletrico | C5: BR | D5: OFFICIAL_PRIMARY | E5: https://dados.ons.org.br/ | F5: Itaipu horario, intercambio internacional, carga Brasil
A6: CAMMESA | B6: Compania Administradora del Mercado Mayorista Electrico | C6: AR | D6: OFFICIAL_PRIMARY | E6: https://cammesaweb.cammesa.com/ | F6: SADI, flujos, variables relevantes, API REST/JSON
A7: BACN | B7: Biblioteca y Archivo Central del Congreso Nacional | C7: PY | D7: OFFICIAL_LEGAL | E7: https://www.bacn.gov.py/ | F7: Tratados y leyes de Itaipu/Yacyreta, terminos economicos
A8: MEF | B8: Ministerio de Economia y Finanzas | C8: PY | D8: OFFICIAL_PRIMARY | E8: https://www.mef.gov.py/ | F8: Transferencias binacionales, royalties, compensaciones
A9: ABC | B9: ABC Color | C9: PY | D9: PRESS_SECONDARY | E9: https://www.abc.com.py/ | F9: Referencias de mercado, precios derivados, contexto comercial
A10: BCP | B10: Banco Central del Paraguay | C10: PY | D10: OFFICIAL_PRIMARY | E10: https://www.bcp.gov.py/ | F10: Tipo de cambio, IPC e indicadores macroeconomicos para normalizacion economica.
A11: WDI_IMF | B11: World Development Indicators / IMF IFS | C11: INTL | D11: OFFICIAL_INTL_SECONDARY | E11: https://data.worldbank.org/ | F11: Backfill y control cruzado de IPC y tipo de cambio anual; BCP sigue siendo la fuente primaria nacional.
A12: NOAA_CPC | B12: NOAA Climate Prediction Center | C12: climate/ENSO | D12: HTML data tables | E12: active | F12: Official ENSO RONI probabilities and strengths
... A14: INE | B14: Instituto Nacional de Estadistica Paraguay | C14: household/demographic | D14: PDF/microdata | E14: active | F14: Census and EPHC

Sheet Source_Documents
A1: document_code | B1: source_code | C1: title | D1: document_type | E1: period_start | F1: period_end | G1: url | H1: authority_class | I1: load_status | J1: notes
A2: ANDE-83-06 | B2: ANDE | C2: Compilacion/Balance de Energia 1983-2006 | D2: historical_statistics | E2: 1983 | F2: 2006 | G2: https://www.ande.gov.py/estadisticas/BalanceEnergia1983-2006/CompilacionEstadistica83-06.pdf | H2: OFFICIAL_PRIMARY | I2: PARTIAL_LOADED | J2: Serie historica antigua; algunos solapes fueron revisados por compilaciones posteriores.
A3: ANDE-90-10 | B3: ANDE | C3: Compilacion Estadistica 1990-2010 | D3: historical_statistics | E3: 1990 | F3: 2010 | G3: https://www.ande.gov.py/documentos_contables/157/compilacion_estadistica_1990-2010.pdf | H3: OFFICIAL_PRIMARY | I3: LOADED | J3: Tarifas y estadisticas historicas.
A4: ANDE-95-15 | B4: ANDE | C4: Compilacion Estadistica 1995-2015 | D4: historical_statistics | E4: 1995 | F4: 2015 | G4: https://www.ande.gov.py/documentos_contables/481/compilacion_estadistica_1995-2015.pdf | H4: OFFICIAL_PRIMARY | I4: REFERENCED | J4: Balance electrico completo 1995-2015.
A5: ANDE-98-18 | B5: ANDE | C5: Compilacion Estadistica 1998-2018 | D5: historical_statistics | E5: 1998 | F5: 2018 | G5: https://www.ande.gov.py/documentos_contables/650/compilacion_estadistica_1998-2018.pdf | H5: OFFICIAL_PRIMARY | I5: LOADED | J5: Energia facturada y exportacion revisadas.
A6: ANDE-03-23 | B6: ANDE | C6: Compilacion Estadistica 2003-2023 | D6: historical_statistics | E6: 2003 | F6: 2023 | G6: https://www.ande.gov.py/finanzas/2.%20COMPILACION%20ESTADISTICA%202003-2023/ANDE%20-%20Compilacion%20Estadistica%202003-2023.pdf | H6: OFFICIAL_PRIMARY | I6: LOADED | J6: Serie principal SIN, balance, infraestructura, tarifas.
A7: ANDE-20-24 | B7: ANDE | C7: Resumen Estadistico 2020-2024 | D7: historical_statistics | E7: 2020 | F7: 2024 | G7: https://www.ande.gov.py/finanzas/ANDE%20-%20Resumen%20Estad%C3%ADstico%202020%20-%202024.pdf | H7: OFFICIAL_PRIMARY | I7: LOADED | J7: Regiones, perdidas, exportacion 2024.
A8: ANDE-BAGP-2025 | B8: ANDE | C8: Balance Anual de Gestion Publica 2025 | D8: annual_report | E8: 2025 | F8: 2025 | G8: https://www.ande.gov.py/finanzas/BAGP%202025%20ANDE.pdf | H8: OFFICIAL_PRIMARY | I8: LOADED | J8: Consumo, demanda maxima y exportacion ENARSA.
A9: ANDE-TARIFF-CURRENT | B9: ANDE | C9: Tarifas vigentes | D9: tariff | E9: current | F9: current | G9: https://www.ande.gov.py/tarifas_vigentes.php | H9: OFFICIAL_PRIMARY | I9: LOADED | J9: Pliego Tarifario 21 vigente: tarifas residenciales normales y reglas de tarifa social incorporadas en v3.
A10: ANDE-ACL-2024 | B10: ANDE | C10: Concurso de venta de energia al ACL Brasil 2738/2024 | D10: market_tender | E10: 2024 | F10: 2024 | G10: https://www.ande.gov.py/interna_contrataciones.php?id=2844 | H10: OFFICIAL_PRIMARY | I10: REFERENCED | J10: Oferta de bloque 100 MW medios Acaray.
A11: ITAIPU-MEM-2002 | B11: ITAIPU | C11: Memoria Anual 2002 | D11: annual_report | E11: 1984 | F11: 2002 | G11: https://www.itaipu.gov.py/sites/default/files/af_df/Memoria%20Anual%202002.pdf | H11: OFFICIAL_PRIMARY | I11: LOADED | J11: Produccion anual 1984-2002.
A12: ITAIPU-MEM-2023 | B12: ITAIPU | C12: Memoria Anual 2023 | D12: annual_report | E12: 2022 | F12: 2023 | G12: https://www.itaipu.gov.py/sites/default/files/u62/Memoria%20Anual%20Itaipu%202023_Espa%C3%B1ol_internet.pdf | H12: OFFICIAL_PRIMARY | I12: LOADED | J12: Suministro mensual 2023 y comparativo 2022.
... A39: WDI-INFL-PRY | B39: WDI_IMF | C39: Inflation consumer prices - Paraguay | D39: macro_backfill | E39: 1990 | F39: 2025 | G39: https://data.worldbank.org/indicator/FP.CPI.TOTL.ZG?locations=PY | H39: OFFICIAL_INTL_SECONDARY | I39: LOADED | J39: Inflacion anual usada para continuidad y control cruzado del CPI.

Sheet Assets
A1: code | B1: name | C1: type | D1: country | E1: lat | F1: lon | G1: notes
A2: PY_SIN | B2: Sistema Interconectado Nacional Paraguay | C2: system | D2: PY | G2: Sistema nacional paraguayo
A3: ITAIPU | B3: Itaipu Binacional | C3: hydro_plant | D3: PY/BR | E3: -25.407 | F3: -54.588 | G3: Coordenada de referencia; validar con capa GIS oficial antes de produccion
A4: YACYRETA | B4: Central Hidroelectrica Yacyreta | C4: hydro_plant | D4: PY/AR | E4: -27.482 | F4: -56.738 | G4: Coordenada de referencia; validar con capa GIS oficial
A5: ACARAY | B5: Central Hidroelectrica Acaray | C5: hydro_plant | D5: PY | E5: -25.455 | F5: -54.632 | G5: Coordenada de referencia; validar con capa GIS oficial
A6: SADI | B6: Sistema Argentino de Interconexion | C6: system | D6: AR | G6: Sistema argentino
A7: BR_SIN | B7: Sistema Interligado Nacional Brasil | C7: system | D7: BR | G7: Sistema brasileño
A8: ENARSA | B8: Energia Argentina S.A. (ENARSA) | C8: counterparty | D8: AR | G8: Comprador/exportacion ANDE
A9: COPEL | B9: COPEL | C9: counterparty | D9: BR | G9: Interconexion historica Acaray-Foz desde 1969
A10: SMD_ITAIPU | B10: Subestacion Margen Derecha Itaipu | C10: substation | D10: PY | G10: Nodo previsto para ventas al ACL Brasil
A11: ACARAY_CONVERTER | B11: Conversora/Interconexion Acaray | C11: interconnection | D11: PY/BR | G11: Intercambio internacional Paraguay-Brasil
A12: SOLAR_PTO_ESPERANZA | B12: Planta Fotovoltaica Puerto Esperanza | C12: solar_plant | D12: PY | G12: GIS oficial pendiente
A13: PY_GRID | B13: Paraguay electricity grid | C13: grid | D13: PY | G13: National grid/quality aggregate asset
A14: PY_GRID_METRO | B14: Metropolitan electricity system | C14: grid_region | D14: PY | G14: Metropolitan quality scope
A15: PY_ECONOMY | B15: Paraguay economy | C15: macro | D15: PY | G15: Macro feature namespace
A16: PY_HOUSEHOLDS | B16: Paraguay households | C16: population | D16: PY | G16: Household/citizenship feature namespace
A17: PY_CLIMATE | B17: Paraguay climate | C17: climate | D17: PY | G17: Climate feature namespace
... A19: ITUZAINGO | B19: Ituzaingo river gauge/port | C19: hydrology_gauge | D19: AR | G19: Reference gauge in EBY operational reports

Sheet Measurements
A1: record_id | B1: period_start | C1: period_end | D1: grain | E1: variable_code | F1: asset_code | G1: origin_code | H1: destination_code | I1: value_source | J1: unit_source | K1: value_normalized | L1: unit_normalized | M1: source_code | N1: authority_class | O1: quality_class | P1: canonical_flag | Q1: revision_priority | R1: source_url | S1: source_file_code | T1: source_published_at | U1: collected_at | V1: notes
A2: R0000001 | B2: 2003-01-01 | C2: 2003-12-31 | D2: year | E2: PY_CONSUMPTION_ENERGY | F2: PY_SIN | G2: PY | H2: PY | I2: 6183000 | J2: MWh | K2: 6183000 | L2: MWh | M2: ANDE | N2: OFFICIAL_PRIMARY | O2: OFFICIAL_AGGREGATE | P2: 1 | Q2: 50 | R2: https://www.ande.gov.py/finanzas/2.%20COMPILACION%20ESTADISTICA%202003-2023/ANDE%20-%20Compilacion%20Estadistica%202003-2023.pdf | S2: ANDE-STAT-2003-2023 | U2: 2026-09-10 23:00:00
A3: R0000002 | B3: 2003-01-01 | C3: 2003-12-31 | D3: year | E3: PY_MAX_DEMAND | F3: PY_SIN | G3: PY | H3: PY | I3: 1191 | J3: MW | K3: 1191 | L3: MW | M3: ANDE | N3: OFFICIAL_PRIMARY | O3: OFFICIAL_AGGREGATE | P3: 1 | Q3: 50 | R3: https://www.ande.gov.py/finanzas/2.%20COMPILACION%20ESTADISTICA%202003-2023/ANDE%20-%20Compilacion%20Estadistica%202003-2023.pdf | S3: ANDE-STAT-2003-2023 | U3: 2026-09-10 23:00:00
A4: R0000003 | B4: 2004-01-01 | C4: 2004-12-31 | D4: year | E4: PY_CONSUMPTION_ENERGY | F4: PY_SIN | G4: PY | H4: PY | I4: 6580000 | J4: MWh | K4: 6580000 | L4: MWh | M4: ANDE | N4: OFFICIAL_PRIMARY | O4: OFFICIAL_AGGREGATE | P4: 1 | Q4: 50 | R4: https://www.ande.gov.py/finanzas/2.%20COMPILACION%20ESTADISTICA%202003-2023/ANDE%20-%20Compilacion%20Estadistica%202003-2023.pdf | S4: ANDE-STAT-2003-2023 | U4: 2026-09-10 23:00:00
A5: R0000004 | B5: 2004-01-01 | C5: 2004-12-31 | D5: year | E5: PY_MAX_DEMAND | F5: PY_SIN | G5: PY | H5: PY | I5: 1241 | J5: MW | K5: 1241 | L5: MW | M5: ANDE | N5: OFFICIAL_PRIMARY | O5: OFFICIAL_AGGREGATE | P5: 1 | Q5: 50 | R5: https://www.ande.gov.py/finanzas/2.%20COMPILACION%20ESTADISTICA%202003-2023/ANDE%20-%20Compilacion%20Estadistica%202003-2023.pdf | S5: ANDE-STAT-2003-2023 | U5: 2026-09-10 23:00:00
A6: R0000005 | B6: 2005-01-01 | C6: 2005-12-31 | D6: year | E6: PY_CONSUMPTION_ENERGY | F6: PY_SIN | G6: PY | H6: PY | I6: 6944000 | J6: MWh | K6: 6944000 | L6: MWh | M6: ANDE | N6: OFFICIAL_PRIMARY | O6: OFFICIAL_AGGREGATE | P6: 1 | Q6: 50 | R6: https://www.ande.gov.py/finanzas/2.%20COMPILACION%20ESTADISTICA%202003-2023/ANDE%20-%20Compilacion%20Estadistica%202003-2023.pdf | S6: ANDE-STAT-2003-2023 | U6: 2026-09-10 23:00:00
A7: R0000006 | B7: 2005-01-01 | C7: 2005-12-31 | D7: year | E7: PY_MAX_DEMAND | F7: PY_SIN | G7: PY | H7: PY | I7: 1354 | J7: MW | K7: 1354 | L7: MW | M7: ANDE | N7: OFFICIAL_PRIMARY | O7: OFFICIAL_AGGREGATE | P7: 1 | Q7: 50 | R7: https://www.ande.gov.py/finanzas/2.%20COMPILACION%20ESTADISTICA%202003-2023/ANDE%20-%20Compilacion%20Estadistica%202003-2023.pdf | S7: ANDE-STAT-2003-2023 | U7: 2026-09-10 23:00:00
A8: R0000007 | B8: 2006-01-01 | C8: 2006-12-31 | D8: year | E8: PY_CONSUMPTION_ENERGY | F8: PY_SIN | G8: PY | H8: PY | I8: 7701000 | J8: MWh | K8: 7701000 | L8: MWh | M8: ANDE | N8: OFFICIAL_PRIMARY | O8: OFFICIAL_AGGREGATE | P8: 1 | Q8: 50 | R8: https://www.ande.gov.py/finanzas/2.%20COMPILACION%20ESTADISTICA%202003-2023/ANDE%20-%20Compilacion%20Estadistica%202003-2023.pdf | S8: ANDE-STAT-2003-2023 | U8: 2026-09-10 23:00:00
A9: R0000008 | B9: 2006-01-01 | C9: 2006-12-31 | D9: year | E9: PY_MAX_DEMAND | F9: PY_SIN | G9: PY | H9: PY | I9: 1450 | J9: MW | K9: 1450 | L9: MW | M9: ANDE | N9: OFFICIAL_PRIMARY | O9: OFFICIAL_AGGREGATE | P9: 1 | Q9: 50 | R9: https://www.ande.gov.py/finanzas/2.%20COMPILACION%20ESTADISTICA%202003-2023/ANDE%20-%20Compilacion%20Estadistica%202003-2023.pdf | S9: ANDE-STAT-2003-2023 | U9: 2026-09-10 23:00:00
A10: R0000009 | B10: 2007-01-01 | C10: 2007-12-31 | D10: year | E10: PY_CONSUMPTION_ENERGY | F10: PY_SIN | G10: PY | H10: PY | I10: 8299000 | J10: MWh | K10: 8299000 | L10: MWh | M10: ANDE | N10: OFFICIAL_PRIMARY | O10: OFFICIAL_AGGREGATE | P10: 1 | Q10: 50 | R10: https://www.ande.gov.py/finanzas/2.%20COMPILACION%20ESTADISTICA%202003-2023/ANDE%20-%20Compilacion%20Estadistica%202003-2023.pdf | S10: ANDE-STAT-2003-2023 | U10: 2026-09-10 23:00:00
A11: R0000010 | B11: 2007-01-01 | C11: 2007-12-31 | D11: year | E11: PY_MAX_DEMAND | F11: PY_SIN | G11: PY | H11: PY | I11: 1521 | J11: MW | K11: 1521 | L11: MW | M11: ANDE | N11: OFFICIAL_PRIMARY | O11: OFFICIAL_AGGREGATE | P11: 1 | Q11: 50 | R11: https://www.ande.gov.py/finanzas/2.%20COMPILACION%20ESTADISTICA%202003-2023/ANDE%20-%20Compilacion%20Estadistica%202003-2023.pdf | S11: ANDE-STAT-2003-2023 | U11: 2026-09-10 23:00:00
A12: R0000011 | B12: 2008-01-01 | C12: 2008-12-31 | D12: year | E12: PY_CONSUMPTION_ENERGY | F12: PY_SIN | G12: PY | H12: PY | I12: 8888000 | J12: MWh | K12: 8888000 | L12: MWh | M12: ANDE | N12: OFFICIAL_PRIMARY | O12: OFFICIAL_AGGREGATE | P12: 1 | Q12: 50 | R12: https://www.ande.gov.py/finanzas/2.%20COMPILACION%20ESTADISTICA%202003-2023/ANDE%20-%20Compilacion%20Estadistica%202003-2023.pdf | S12: ANDE-STAT-2003-2023 | U12: 2026-09-10 23:00:00
A13: R0000012 | B13: 2008-01-01 | C13: 2008-12-31 | D13: year | E13: PY_MAX_DEMAND | F13: PY_SIN | G13: PY | H13: PY | I13: 1648 | J13: MW | K13: 1648 | L13: MW | M13: ANDE | N13: OFFICIAL_PRIMARY | O13: OFFICIAL_AGGREGATE | P13: 1 | Q13: 50 | R13: https://www.ande.gov.py/finanzas/2.%20COMPILACION%20ESTADISTICA%202003-2023/ANDE%20-%20Compilacion%20Estadistica%202003-2023.pdf | S13: ANDE-STAT-2003-2023 | U13: 2026-09-10 23:00:00
... A37: R0000036 | B37: 2020-01-01 | C37: 2020-12-31 | D37: year | E37: PY_MAX_DEMAND | F37: PY_SIN | G37: PY | H37: PY | I37: 3563 | J37: MW | K37: 3563 | L37: MW | M37: ANDE | N37: OFFICIAL_PRIMARY | O37: OFFICIAL_AGGREGATE | P37: 1 | Q37: 50 | R37: https://www.ande.gov.py/finanzas/2.%20COMPILACION%20ESTADISTICA%202003-2023/ANDE%20-%20Compilacion%20Estadistica%202003-2023.pdf | S37: ANDE-STAT-2003-2023 | U37: 2026-09-10 23:00:00
A38: R0000037 | B38: 2020-01-01 | C38: 2020-12-31 | D38: year | E38: PY_LOAD_FACTOR | F38: PY_SIN | G38: PY | H38: PY | I38: 57.5 | J38: percent | K38: 57.5 | L38: percent | M38: ANDE | N38: OFFICIAL_PRIMARY | O38: OFFICIAL_AGGREGATE | P38: 1 | Q38: 50 | R38: https://www.ande.gov.py/finanzas/2.%20COMPILACION%20ESTADISTICA%202003-2023/ANDE%20-%20Compilacion%20Estadistica%202003-2023.pdf | S38: ANDE-STAT-2003-2023 | U38: 2026-09-10 23:00:00 | V38: Factor de carga publicado.
A39: R0000038 | B39: 2021-01-01 | C39: 2021-12-31 | D39: year | E39: PY_CONSUMPTION_ENERGY | F39: PY_SIN | G39: PY | H39: PY | I39: 18583322 | J39: MWh | K39: 18583322 | L39: MWh | M39: ANDE | N39: OFFICIAL_PRIMARY | O39: OFFICIAL_AGGREGATE | P39: 0 | Q39: 50 | R39: https://www.ande.gov.py/finanzas/2.%20COMPILACION%20ESTADISTICA%202003-2023/ANDE%20-%20Compilacion%20Estadistica%202003-2023.pdf | S39: ANDE-STAT-2003-2023 | U39: 2026-09-10 23:00:00
A40: R0000039 | B40: 2021-01-01 | C40: 2021-12-31 | D40: year | E40: PY_MAX_DEMAND | F40: PY_SIN | G40: PY | H40: PY | I40: 3777 | J40: MW | K40: 3777 | L40: MW | M40: ANDE | N40: OFFICIAL_PRIMARY | O40: OFFICIAL_AGGREGATE | P40: 1 | Q40: 50 | R40: https://www.ande.gov.py/finanzas/2.%20COMPILACION%20ESTADISTICA%202003-2023/ANDE%20-%20Compilacion%20Estadistica%202003-2023.pdf | S40: ANDE-STAT-2003-2023 | U40: 2026-09-10 23:00:00
A41: R0000040 | B41: 2021-01-01 | C41: 2021-12-31 | D41: year | E41: PY_LOAD_FACTOR | F41: PY_SIN | G41: PY | H41: PY | I41: 56.2 | J41: percent | K41: 56.2 | L41: percent | M41: ANDE | N41: OFFICIAL_PRIMARY | O41: OFFICIAL_AGGREGATE | P41: 1 | Q41: 50 | R41: https://www.ande.gov.py/finanzas/2.%20COMPILACION%20ESTADISTICA%202003-2023/ANDE%20-%20Compilacion%20Estadistica%202003-2023.pdf | S41: ANDE-STAT-2003-2023 | U41: 2026-09-10 23:00:00 | V41: Factor de carga publicado.
A42: R0000041 | B42: 2022-01-01 | C42: 2022-12-31 | D42: year | E42: PY_CONSUMPTION_ENERGY | F42: PY_SIN | G42: PY | H42: PY | I42: 19634614 | J42: MWh | K42: 19634614 | L42: MWh | M42: ANDE | N42: OFFICIAL_PRIMARY | O42: OFFICIAL_AGGREGATE | P42: 0 | Q42: 50 | R42: https://www.ande.gov.py/finanzas/2.%20COMPILACION%20ESTADISTICA%202003-2023/ANDE%20-%20Compilacion%20Estadistica%202003-2023.pdf | S42: ANDE-STAT-2003-2023 | U42: 2026-09-10 23:00:00
A43: R0000042 | B43: 2022-01-01 | C43: 2022-12-31 | D43: year | E43: PY_MAX_DEMAND | F43: PY_SIN | G43: PY | H43: PY | I43: 4270 | J43: MW | K43: 4270 | L43: MW | M43: ANDE | N43: OFFICIAL_PRIMARY | O43: OFFICIAL_AGGREGATE | P43: 1 | Q43: 50 | R43: https://www.ande.gov.py/finanzas/2.%20COMPILACION%20ESTADISTICA%202003-2023/ANDE%20-%20Compilacion%20Estadistica%202003-2023.pdf | S43: ANDE-STAT-2003-2023 | U43: 2026-09-10 23:00:00
A44: R0000043 | B44: 2022-01-01 | C44: 2022-12-31 | D44: year | E44: PY_LOAD_FACTOR | F44: PY_SIN | G44: PY | H44: PY | I44: 52.5 | J44: percent | K44: 52.5 | L44: percent | M44: ANDE | N44: OFFICIAL_PRIMARY | O44: OFFICIAL_AGGREGATE | P44: 1 | Q44: 50 | R44: https://www.ande.gov.py/finanzas/2.%20COMPILACION%20ESTADISTICA%202003-2023/ANDE%20-%20Compilacion%20Estadistica%202003-2023.pdf | S44: ANDE-STAT-2003-2023 | U44: 2026-09-10 23:00:00 | V44: Factor de carga publicado.
A45: R0000044 | B45: 2023-01-01 | C45: 2023-12-31 | D45: year | E45: PY_CONSUMPTION_ENERGY | F45: PY_SIN | G45: PY | H45: PY | I45: 22078726 | J45: MWh | K45: 22078726 | L45: MWh | M45: ANDE | N45: OFFICIAL_PRIMARY | O45: OFFICIAL_AGGREGATE | P45: 0 | Q45: 50 | R45: https://www.ande.gov.py/finanzas/2.%20COMPILACION%20ESTADISTICA%202003-2023/ANDE%20-%20Compilacion%20Estadistica%202003-2023.pdf | S45: ANDE-STAT-2003-2023 | U45: 2026-09-10 23:00:00
A46: R0000045 | B46: 2023-01-01 | C46: 2023-12-31 | D46: year | E46: PY_MAX_DEMAND | F46: PY_SIN | G46: PY | H46: PY | I46: 4744 | J46: MW | K46: 4744 | L46: MW | M46: ANDE | N46: OFFICIAL_PRIMARY | O46: OFFICIAL_AGGREGATE | P46: 1 | Q46: 50 | R46: https://www.ande.gov.py/finanzas/2.%20COMPILACION%20ESTADISTICA%202003-2023/ANDE%20-%20Compilacion%20Estadistica%202003-2023.pdf | S46: ANDE-STAT-2003-2023 | U46: 2026-09-10 23:00:00
A47: R0000046 | B47: 2023-01-01 | C47: 2023-12-31 | D47: year | E47: PY_LOAD_FACTOR | F47: PY_SIN | G47: PY | H47: PY | I47: 53.1 | J47: percent | K47: 53.1 | L47: percent | M47: ANDE | N47: OFFICIAL_PRIMARY | O47: OFFICIAL_AGGREGATE | P47: 1 | Q47: 50 | R47: https://www.ande.gov.py/finanzas/2.%20COMPILACION%20ESTADISTICA%202003-2023/ANDE%20-%20Compilacion%20Estadistica%202003-2023.pdf | S47: ANDE-STAT-2003-2023 | U47: 2026-09-10 23:00:00 | V47: Factor de carga publicado.
A48: R0000047 | B48: 2024-01-01 | C48: 2024-12-31 | D48: year | E48: PY_CONSUMPTION_ENERGY | F48: PY_SIN | G48: PY | H48: PY | I48: 26154488 | J48: MWh | K48: 26154488 | L48: MWh | M48: ANDE | N48: OFFICIAL_PRIMARY | O48: OFFICIAL_AGGREGATE | P48: 1 | Q48: 50 | R48: https://www.ande.gov.py/finanzas/ANDE%20-%20Resumen%20Estad%C3%ADstico%202020%20-%202024.pdf | S48: ANDE-STAT-2020-2024 | U48: 2026-09-10 23:00:00
A49: R0000048 | B49: 2024-01-01 | C49: 2024-12-31 | D49: year | E49: PY_MAX_DEMAND | F49: PY_SIN | G49: PY | H49: PY | I49: 5027 | J49: MW | K49: 5027 | L49: MW | M49: ANDE | N49: OFFICIAL_PRIMARY | O49: OFFICIAL_AGGREGATE | P49: 1 | Q49: 50 | R49: https://www.ande.gov.py/finanzas/ANDE%20-%20Resumen%20Estad%C3%ADstico%202020%20-%202024.pdf | S49: ANDE-STAT-2020-2024 | U49: 2026-09-10 23:00:00
A50: R0000049 | B50: 2024-01-01 | C50: 2024-12-31 | D50: year | E50: PY_LOAD_FACTOR | F50: PY_SIN | G50: PY | H50: PY | I50: 59.39 | J50: percent | K50: 59.39 | L50: percent | M50: ANDE | N50: OFFICIAL_PRIMARY | O50: OFFICIAL_AGGREGATE | P50: 1 | Q50: 50 | R50: https://www.ande.gov.py/finanzas/ANDE%20-%20Resumen%20Estad%C3%ADstico%202020%20-%202024.pdf | S50: ANDE-STAT-2020-2024 | U50: 2026-09-10 23:00:00 | V50: Factor de carga publicado.
A51: R0000050 | B51: 2025-01-01 | C51: 2025-12-31 | D51: year | E51: PY_CONSUMPTION_ENERGY | F51: PY_SIN | G51: PY | H51: PY | I51: 29418538 | J51: MWh | K51: 29418538 | L51: MWh | M51: ANDE | N51: OFFICIAL_PRIMARY | O51: OFFICIAL_AGGREGATE | P51: 1 | Q51: 50 | R51: https://www.ande.gov.py/finanzas/BAGP%202025%20ANDE.pdf | S51: ANDE-BAGP-2025 | U51: 2026-09-10 23:00:00 | V51: 2025: total exacto de BAGP; nota de prensa redondea a 29.419 GWh.
A52: R0000051 | B52: 2025-01-01 | C52: 2025-12-31 | D52: year | E52: PY_MAX_DEMAND | F52: PY_SIN | G52: PY | H52: PY | I52: 5280 | J52: MW | K52: 5280 | L52: MW | M52: ANDE | N52: OFFICIAL_PRIMARY | O52: OFFICIAL_AGGREGATE | P52: 1 | Q52: 50 | R52: https://www.ande.gov.py/finanzas/BAGP%202025%20ANDE.pdf | S52: ANDE-BAGP-2025 | U52: 2026-09-10 23:00:00 | V52: 2025: total exacto de BAGP; nota de prensa redondea a 29.419 GWh.
A53: R0000052 | B53: 2025-01-01 | C53: 2025-12-31 | D53: year | E53: PY_LOAD_FACTOR | F53: PY_SIN | G53: PY | H53: PY | I53: 63.6 | J53: percent | K53: 63.6 | L53: percent | M53: ANDE | N53: OFFICIAL_PRIMARY | O53: OFFICIAL_AGGREGATE | P53: 1 | Q53: 50 | R53: https://www.ande.gov.py/finanzas/BAGP%202025%20ANDE.pdf | S53: ANDE-BAGP-2025 | U53: 2026-09-10 23:00:00 | V53: Factor de carga publicado.
A54: R0000053 | B54: 2020-01-01 | C54: 2020-12-31 | D54: year | E54: PY_REGION_ENERGY | F54: PY_REGION_METROPOLITANO | G54: PY | H54: PY | I54: 9312851 | J54: MWh | K54: 9312851 | L54: MWh | M54: ANDE | N54: OFFICIAL_PRIMARY | O54: OFFICIAL_AGGREGATE | P54: 1 | Q54: 50 | R54: https://www.ande.gov.py/finanzas/ANDE%20-%20Resumen%20Estad%C3%ADstico%202020%20-%202024.pdf | S54: ANDE-STAT-2020-2024 | U54: 2026-09-10 23:00:00 | V54: Sistema/region: Metropolitano.
A55: R0000054 | B55: 2021-01-01 | C55: 2021-12-31 | D55: year | E55: PY_REGION_ENERGY | F55: PY_REGION_METROPOLITANO | G55: PY | H55: PY | I55: 9543744 | J55: MWh | K55: 9543744 | L55: MWh | M55: ANDE | N55: OFFICIAL_PRIMARY | O55: OFFICIAL_AGGREGATE | P55: 1 | Q55: 50 | R55: https://www.ande.gov.py/finanzas/ANDE%20-%20Resumen%20Estad%C3%ADstico%202020%20-%202024.pdf | S55: ANDE-STAT-2020-2024 | U55: 2026-09-10 23:00:00 | V55: Sistema/region: Metropolitano.
A56: R0000055 | B56: 2022-01-01 | C56: 2022-12-31 | D56: year | E56: PY_REGION_ENERGY | F56: PY_REGION_METROPOLITANO | G56: PY | H56: PY | I56: 9964357 | J56: MWh | K56: 9964357 | L56: MWh | M56: ANDE | N56: OFFICIAL_PRIMARY | O56: OFFICIAL_AGGREGATE | P56: 1 | Q56: 50 | R56: https://www.ande.gov.py/finanzas/ANDE%20-%20Resumen%20Estad%C3%ADstico%202020%20-%202024.pdf | S56: ANDE-STAT-2020-2024 | U56: 2026-09-10 23:00:00 | V56: Sistema/region: Metropolitano.
A57: R0000056 | B57: 2023-01-01 | C57: 2023-12-31 | D57: year | E57: PY_REGION_ENERGY | F57: PY_REGION_METROPOLITANO | G57: PY | H57: PY | I57: 11174060 | J57: MWh | K57: 11174060 | L57: MWh | M57: ANDE | N57: OFFICIAL_PRIMARY | O57: OFFICIAL_AGGREGATE | P57: 1 | Q57: 50 | R57: https://www.ande.gov.py/finanzas/ANDE%20-%20Resumen%20Estad%C3%ADstico%202020%20-%202024.pdf | S57: ANDE-STAT-2020-2024 | U57: 2026-09-10 23:00:00 | V57: Sistema/region: Metropolitano.
A58: R0000057 | B58: 2024-01-01 | C58: 2024-12-31 | D58: year | E58: PY_REGION_ENERGY | F58: PY_REGION_METROPOLITANO | G58: PY | H58: PY | I58: 12291090 | J58: MWh | K58: 12291090 | L58: MWh | M58: ANDE | N58: OFFICIAL_PRIMARY | O58: OFFICIAL_AGGREGATE | P58: 1 | Q58: 50 | R58: https://www.ande.gov.py/finanzas/ANDE%20-%20Resumen%20Estad%C3%ADstico%202020%20-%202024.pdf | S58: ANDE-STAT-2020-2024 | U58: 2026-09-10 23:00:00 | V58: Sistema/region: Metropolitano.
A59: R0000058 | B59: 2020-01-01 | C59: 2020-12-31 | D59: year | E59: PY_REGION_ENERGY | F59: PY_REGION_CENTRAL | G59: PY | H59: PY | I59: 1833781 | J59: MWh | K59: 1833781 | L59: MWh | M59: ANDE | N59: OFFICIAL_PRIMARY | O59: OFFICIAL_AGGREGATE | P59: 1 | Q59: 50 | R59: https://www.ande.gov.py/finanzas/ANDE%20-%20Resumen%20Estad%C3%ADstico%202020%20-%202024.pdf | S59: ANDE-STAT-2020-2024 | U59: 2026-09-10 23:00:00 | V59: Sistema/region: Central.
A60: R0000059 | B60: 2021-01-01 | C60: 2021-12-31 | D60: year | E60: PY_REGION_ENERGY | F60: PY_REGION_CENTRAL | G60: PY | H60: PY | I60: 1985053 | J60: MWh | K60: 1985053 | L60: MWh | M60: ANDE | N60: OFFICIAL_PRIMARY | O60: OFFICIAL_AGGREGATE | P60: 1 | Q60: 50 | R60: https://www.ande.gov.py/finanzas/ANDE%20-%20Resumen%20Estad%C3%ADstico%202020%20-%202024.pdf | S60: ANDE-STAT-2020-2024 | U60: 2026-09-10 23:00:00 | V60: Sistema/region: Central.
A61: R0000060 | B61: 2022-01-01 | C61: 2022-12-31 | D61: year | E61: PY_REGION_ENERGY | F61: PY_REGION_CENTRAL | G61: PY | H61: PY | I61: 2373625 | J61: MWh | K61: 2373625 | L61: MWh | M61: ANDE | N61: OFFICIAL_PRIMARY | O61: OFFICIAL_AGGREGATE | P61: 1 | Q61: 50 | R61: https://www.ande.gov.py/finanzas/ANDE%20-%20Resumen%20Estad%C3%ADstico%202020%20-%202024.pdf | S61: ANDE-STAT-2020-2024 | U61: 2026-09-10 23:00:00 | V61: Sistema/region: Central.
... A142: R0000141 | B142: 2026-01-01 | C142: 2026-05-31 | D142: period | E142: PY_CONSUMPTION_ENERGY_YTD | F142: PY_SIN | G142: PY | H142: PY | I142: 14587100 | J142: MWh | K142: 14587100 | L142: MWh | M142: ANDE | N142: OFFICIAL_PRIMARY | O142: OFFICIAL_AGGREGATE | P142: 1 | Q142: 50 | R142: https://www.ande.gov.py/interna.php?id=15361 | S142: ANDE-MAY-2026 | U142: 2026-09-10 23:00:00 | V142: Acumulado enero-mayo publicado por ANDE.
A143: R0000142 | B143: 2025-08-14 06:23:00 | C143: 2025-08-14 06:23:00 | D143: event | E143: PY_DEMAND | F143: PY_SIN | G143: PY | H143: PY | I143: 3070 | J143: MW | K143: 3070 | L143: MW | M143: ANDE | N143: OFFICIAL_PRIMARY | O143: OFFICIAL_MEASURED | P143: 1 | Q143: 50 | R143: https://www.ande.gov.py/interna.php?id=14173 | U143: 2026-09-10 23:00:00 | V143: Evento: Avería en interruptor 220 kV de Acaray; demanda reportada al momento del inconveniente. ANDE indica abastecimiento principalmente por Itaipú; no desglosa MW por central.
...

Sheet Canonical
A1: record_id | B1: period_start | C1: period_end | D1: grain | E1: variable_code | F1: asset_code | G1: origin_code | H1: destination_code | I1: value_source | J1: unit_source | K1: value_normalized | L1: unit_normalized | M1: source_code | N1: authority_class | O1: quality_class | P1: canonical_flag | Q1: revision_priority | R1: source_url | S1: source_file_code | T1: source_published_at | U1: collected_at | V1: notes
A2: R0000001 | B2: 2003-01-01 | C2: 2003-12-31 | D2: year | E2: PY_CONSUMPTION_ENERGY | F2: PY_SIN | G2: PY | H2: PY | I2: 6183000 | J2: MWh | K2: 6183000 | L2: MWh | M2: ANDE | N2: OFFICIAL_PRIMARY | O2: OFFICIAL_AGGREGATE | P2: 1 | Q2: 50 | R2: https://www.ande.gov.py/finanzas/2.%20COMPILACION%20ESTADISTICA%202003-2023/ANDE%20-%20Compilacion%20Estadistica%202003-2023.pdf | S2: ANDE-STAT-2003-2023 | U2: 2026-09-10 23:00:00
A3: R0000002 | B3: 2003-01-01 | C3: 2003-12-31 | D3: year | E3: PY_MAX_DEMAND | F3: PY_SIN | G3: PY | H3: PY | I3: 1191 | J3: MW | K3: 1191 | L3: MW | M3: ANDE | N3: OFFICIAL_PRIMARY | O3: OFFICIAL_AGGREGATE | P3: 1 | Q3: 50 | R3: https://www.ande.gov.py/finanzas/2.%20COMPILACION%20ESTADISTICA%202003-2023/ANDE%20-%20Compilacion%20Estadistica%202003-2023.pdf | S3: ANDE-STAT-2003-2023 | U3: 2026-09-10 23:00:00
A4: R0000003 | B4: 2004-01-01 | C4: 2004-12-31 | D4: year | E4: PY_CONSUMPTION_ENERGY | F4: PY_SIN | G4: PY | H4: PY | I4: 6580000 | J4: MWh | K4: 6580000 | L4: MWh | M4: ANDE | N4: OFFICIAL_PRIMARY | O4: OFFICIAL_AGGREGATE | P4: 1 | Q4: 50 | R4: https://www.ande.gov.py/finanzas/2.%20COMPILACION%20ESTADISTICA%202003-2023/ANDE%20-%20Compilacion%20Estadistica%202003-2023.pdf | S4: ANDE-STAT-2003-2023 | U4: 2026-09-10 23:00:00
A5: R0000004 | B5: 2004-01-01 | C5: 2004-12-31 | D5: year | E5: PY_MAX_DEMAND | F5: PY_SIN | G5: PY | H5: PY | I5: 1241 | J5: MW | K5: 1241 | L5: MW | M5: ANDE | N5: OFFICIAL_PRIMARY | O5: OFFICIAL_AGGREGATE | P5: 1 | Q5: 50 | R5: https://www.ande.gov.py/finanzas/2.%20COMPILACION%20ESTADISTICA%202003-2023/ANDE%20-%20Compilacion%20Estadistica%202003-2023.pdf | S5: ANDE-STAT-2003-2023 | U5: 2026-09-10 23:00:00
A6: R0000005 | B6: 2005-01-01 | C6: 2005-12-31 | D6: year | E6: PY_CONSUMPTION_ENERGY | F6: PY_SIN | G6: PY | H6: PY | I6: 6944000 | J6: MWh | K6: 6944000 | L6: MWh | M6: ANDE | N6: OFFICIAL_PRIMARY | O6: OFFICIAL_AGGREGATE | P6: 1 | Q6: 50 | R6: https://www.ande.gov.py/finanzas/2.%20COMPILACION%20ESTADISTICA%202003-2023/ANDE%20-%20Compilacion%20Estadistica%202003-2023.pdf | S6: ANDE-STAT-2003-2023 | U6: 2026-09-10 23:00:00
A7: R0000006 | B7: 2005-01-01 | C7: 2005-12-31 | D7: year | E7: PY_MAX_DEMAND | F7: PY_SIN | G7: PY | H7: PY | I7: 1354 | J7: MW | K7: 1354 | L7: MW | M7: ANDE | N7: OFFICIAL_PRIMARY | O7: OFFICIAL_AGGREGATE | P7: 1 | Q7: 50 | R7: https://www.ande.gov.py/finanzas/2.%20COMPILACION%20ESTADISTICA%202003-2023/ANDE%20-%20Compilacion%20Estadistica%202003-2023.pdf | S7: ANDE-STAT-2003-2023 | U7: 2026-09-10 23:00:00
A8: R0000007 | B8: 2006-01-01 | C8: 2006-12-31 | D8: year | E8: PY_CONSUMPTION_ENERGY | F8: PY_SIN | G8: PY | H8: PY | I8: 7701000 | J8: MWh | K8: 7701000 | L8: MWh | M8: ANDE | N8: OFFICIAL_PRIMARY | O8: OFFICIAL_AGGREGATE | P8: 1 | Q8: 50 | R8: https://www.ande.gov.py/finanzas/2.%20COMPILACION%20ESTADISTICA%202003-2023/ANDE%20-%20Compilacion%20Estadistica%202003-2023.pdf | S8: ANDE-STAT-2003-2023 | U8: 2026-09-10 23:00:00
A9: R0000008 | B9: 2006-01-01 | C9: 2006-12-31 | D9: year | E9: PY_MAX_DEMAND | F9: PY_SIN | G9: PY | H9: PY | I9: 1450 | J9: MW | K9: 1450 | L9: MW | M9: ANDE | N9: OFFICIAL_PRIMARY | O9: OFFICIAL_AGGREGATE | P9: 1 | Q9: 50 | R9: https://www.ande.gov.py/finanzas/2.%20COMPILACION%20ESTADISTICA%202003-2023/ANDE%20-%20Compilacion%20Estadistica%202003-2023.pdf | S9: ANDE-STAT-2003-2023 | U9: 2026-09-10 23:00:00
A10: R0000009 | B10: 2007-01-01 | C10: 2007-12-31 | D10: year | E10: PY_CONSUMPTION_ENERGY | F10: PY_SIN | G10: PY | H10: PY | I10: 8299000 | J10: MWh | K10: 8299000 | L10: MWh | M10: ANDE | N10: OFFICIAL_PRIMARY | O10: OFFICIAL_AGGREGATE | P10: 1 | Q10: 50 | R10: https://www.ande.gov.py/finanzas/2.%20COMPILACION%20ESTADISTICA%202003-2023/ANDE%20-%20Compilacion%20Estadistica%202003-2023.pdf | S10: ANDE-STAT-2003-2023 | U10: 2026-09-10 23:00:00
A11: R0000010 | B11: 2007-01-01 | C11: 2007-12-31 | D11: year | E11: PY_MAX_DEMAND | F11: PY_SIN | G11: PY | H11: PY | I11: 1521 | J11: MW | K11: 1521 | L11: MW | M11: ANDE | N11: OFFICIAL_PRIMARY | O11: OFFICIAL_AGGREGATE | P11: 1 | Q11: 50 | R11: https://www.ande.gov.py/finanzas/2.%20COMPILACION%20ESTADISTICA%202003-2023/ANDE%20-%20Compilacion%20Estadistica%202003-2023.pdf | S11: ANDE-STAT-2003-2023 | U11: 2026-09-10 23:00:00
A12: R0000011 | B12: 2008-01-01 | C12: 2008-12-31 | D12: year | E12: PY_CONSUMPTION_ENERGY | F12: PY_SIN | G12: PY | H12: PY | I12: 8888000 | J12: MWh | K12: 8888000 | L12: MWh | M12: ANDE | N12: OFFICIAL_PRIMARY | O12: OFFICIAL_AGGREGATE | P12: 1 | Q12: 50 | R12: https://www.ande.gov.py/finanzas/2.%20COMPILACION%20ESTADISTICA%202003-2023/ANDE%20-%20Compilacion%20Estadistica%202003-2023.pdf | S12: ANDE-STAT-2003-2023 | U12: 2026-09-10 23:00:00
A13: R0000012 | B13: 2008-01-01 | C13: 2008-12-31 | D13: year | E13: PY_MAX_DEMAND | F13: PY_SIN | G13: PY | H13: PY | I13: 1648 | J13: MW | K13: 1648 | L13: MW | M13: ANDE | N13: OFFICIAL_PRIMARY | O13: OFFICIAL_AGGREGATE | P13: 1 | Q13: 50 | R13: https://www.ande.gov.py/finanzas/2.%20COMPILACION%20ESTADISTICA%202003-2023/ANDE%20-%20Compilacion%20Estadistica%202003-2023.pdf | S13: ANDE-STAT-2003-2023 | U13: 2026-09-10 23:00:00
... A36: R0000036 | B36: 2020-01-01 | C36: 2020-12-31 | D36: year | E36: PY_MAX_DEMAND | F36: PY_SIN | G36: PY | H36: PY | I36: 3563 | J36: MW | K36: 3563 | L36: MW | M36: ANDE | N36: OFFICIAL_PRIMARY | O36: OFFICIAL_AGGREGATE | P36: 1 | Q36: 50 | R36: https://www.ande.gov.py/finanzas/2.%20COMPILACION%20ESTADISTICA%202003-2023/ANDE%20-%20Compilacion%20Estadistica%202003-2023.pdf | S36: ANDE-STAT-2003-2023 | U36: 2026-09-10 23:00:00
A37: R0000037 | B37: 2020-01-01 | C37: 2020-12-31 | D37: year | E37: PY_LOAD_FACTOR | F37: PY_SIN | G37: PY | H37: PY | I37: 57.5 | J37: percent | K37: 57.5 | L37: percent | M37: ANDE | N37: OFFICIAL_PRIMARY | O37: OFFICIAL_AGGREGATE | P37: 1 | Q37: 50 | R37: https://www.ande.gov.py/finanzas/2.%20COMPILACION%20ESTADISTICA%202003-2023/ANDE%20-%20Compilacion%20Estadistica%202003-2023.pdf | S37: ANDE-STAT-2003-2023 | U37: 2026-09-10 23:00:00 | V37: Factor de carga publicado.
A38: R0000039 | B38: 2021-01-01 | C38: 2021-12-31 | D38: year | E38: PY_MAX_DEMAND | F38: PY_SIN | G38: PY | H38: PY | I38: 3777 | J38: MW | K38: 3777 | L38: MW | M38: ANDE | N38: OFFICIAL_PRIMARY | O38: OFFICIAL_AGGREGATE | P38: 1 | Q38: 50 | R38: https://www.ande.gov.py/finanzas/2.%20COMPILACION%20ESTADISTICA%202003-2023/ANDE%20-%20Compilacion%20Estadistica%202003-2023.pdf | S38: ANDE-STAT-2003-2023 | U38: 2026-09-10 23:00:00
A39: R0000040 | B39: 2021-01-01 | C39: 2021-12-31 | D39: year | E39: PY_LOAD_FACTOR | F39: PY_SIN | G39: PY | H39: PY | I39: 56.2 | J39: percent | K39: 56.2 | L39: percent | M39: ANDE | N39: OFFICIAL_PRIMARY | O39: OFFICIAL_AGGREGATE | P39: 1 | Q39: 50 | R39: https://www.ande.gov.py/finanzas/2.%20COMPILACION%20ESTADISTICA%202003-2023/ANDE%20-%20Compilacion%20Estadistica%202003-2023.pdf | S39: ANDE-STAT-2003-2023 | U39: 2026-09-10 23:00:00 | V39: Factor de carga publicado.
A40: R0000042 | B40: 2022-01-01 | C40: 2022-12-31 | D40: year | E40: PY_MAX_DEMAND | F40: PY_SIN | G40: PY | H40: PY | I40: 4270 | J40: MW | K40: 4270 | L40: MW | M40: ANDE | N40: OFFICIAL_PRIMARY | O40: OFFICIAL_AGGREGATE | P40: 1 | Q40: 50 | R40: https://www.ande.gov.py/finanzas/2.%20COMPILACION%20ESTADISTICA%202003-2023/ANDE%20-%20Compilacion%20Estadistica%202003-2023.pdf | S40: ANDE-STAT-2003-2023 | U40: 2026-09-10 23:00:00
A41: R0000043 | B41: 2022-01-01 | C41: 2022-12-31 | D41: year | E41: PY_LOAD_FACTOR | F41: PY_SIN | G41: PY | H41: PY | I41: 52.5 | J41: percent | K41: 52.5 | L41: percent | M41: ANDE | N41: OFFICIAL_PRIMARY | O41: OFFICIAL_AGGREGATE | P41: 1 | Q41: 50 | R41: https://www.ande.gov.py/finanzas/2.%20COMPILACION%20ESTADISTICA%202003-2023/ANDE%20-%20Compilacion%20Estadistica%202003-2023.pdf | S41: ANDE-STAT-2003-2023 | U41: 2026-09-10 23:00:00 | V41: Factor de carga publicado.
A42: R0000045 | B42: 2023-01-01 | C42: 2023-12-31 | D42: year | E42: PY_MAX_DEMAND | F42: PY_SIN | G42: PY | H42: PY | I42: 4744 | J42: MW | K42: 4744 | L42: MW | M42: ANDE | N42: OFFICIAL_PRIMARY | O42: OFFICIAL_AGGREGATE | P42: 1 | Q42: 50 | R42: https://www.ande.gov.py/finanzas/2.%20COMPILACION%20ESTADISTICA%202003-2023/ANDE%20-%20Compilacion%20Estadistica%202003-2023.pdf | S42: ANDE-STAT-2003-2023 | U42: 2026-09-10 23:00:00
A43: R0000046 | B43: 2023-01-01 | C43: 2023-12-31 | D43: year | E43: PY_LOAD_FACTOR | F43: PY_SIN | G43: PY | H43: PY | I43: 53.1 | J43: percent | K43: 53.1 | L43: percent | M43: ANDE | N43: OFFICIAL_PRIMARY | O43: OFFICIAL_AGGREGATE | P43: 1 | Q43: 50 | R43: https://www.ande.gov.py/finanzas/2.%20COMPILACION%20ESTADISTICA%202003-2023/ANDE%20-%20Compilacion%20Estadistica%202003-2023.pdf | S43: ANDE-STAT-2003-2023 | U43: 2026-09-10 23:00:00 | V43: Factor de carga publicado.
A44: R0000047 | B44: 2024-01-01 | C44: 2024-12-31 | D44: year | E44: PY_CONSUMPTION_ENERGY | F44: PY_SIN | G44: PY | H44: PY | I44: 26154488 | J44: MWh | K44: 26154488 | L44: MWh | M44: ANDE | N44: OFFICIAL_PRIMARY | O44: OFFICIAL_AGGREGATE | P44: 1 | Q44: 50 | R44: https://www.ande.gov.py/finanzas/ANDE%20-%20Resumen%20Estad%C3%ADstico%202020%20-%202024.pdf | S44: ANDE-STAT-2020-2024 | U44: 2026-09-10 23:00:00
A45: R0000048 | B45: 2024-01-01 | C45: 2024-12-31 | D45: year | E45: PY_MAX_DEMAND | F45: PY_SIN | G45: PY | H45: PY | I45: 5027 | J45: MW | K45: 5027 | L45: MW | M45: ANDE | N45: OFFICIAL_PRIMARY | O45: OFFICIAL_AGGREGATE | P45: 1 | Q45: 50 | R45: https://www.ande.gov.py/finanzas/ANDE%20-%20Resumen%20Estad%C3%ADstico%202020%20-%202024.pdf | S45: ANDE-STAT-2020-2024 | U45: 2026-09-10 23:00:00
A46: R0000049 | B46: 2024-01-01 | C46: 2024-12-31 | D46: year | E46: PY_LOAD_FACTOR | F46: PY_SIN | G46: PY | H46: PY | I46: 59.39 | J46: percent | K46: 59.39 | L46: percent | M46: ANDE | N46: OFFICIAL_PRIMARY | O46: OFFICIAL_AGGREGATE | P46: 1 | Q46: 50 | R46: https://www.ande.gov.py/finanzas/ANDE%20-%20Resumen%20Estad%C3%ADstico%202020%20-%202024.pdf | S46: ANDE-STAT-2020-2024 | U46: 2026-09-10 23:00:00 | V46: Factor de carga publicado.
A47: R0000050 | B47: 2025-01-01 | C47: 2025-12-31 | D47: year | E47: PY_CONSUMPTION_ENERGY | F47: PY_SIN | G47: PY | H47: PY | I47: 29418538 | J47: MWh | K47: 29418538 | L47: MWh | M47: ANDE | N47: OFFICIAL_PRIMARY | O47: OFFICIAL_AGGREGATE | P47: 1 | Q47: 50 | R47: https://www.ande.gov.py/finanzas/BAGP%202025%20ANDE.pdf | S47: ANDE-BAGP-2025 | U47: 2026-09-10 23:00:00 | V47: 2025: total exacto de BAGP; nota de prensa redondea a 29.419 GWh.
A48: R0000051 | B48: 2025-01-01 | C48: 2025-12-31 | D48: year | E48: PY_MAX_DEMAND | F48: PY_SIN | G48: PY | H48: PY | I48: 5280 | J48: MW | K48: 5280 | L48: MW | M48: ANDE | N48: OFFICIAL_PRIMARY | O48: OFFICIAL_AGGREGATE | P48: 1 | Q48: 50 | R48: https://www.ande.gov.py/finanzas/BAGP%202025%20ANDE.pdf | S48: ANDE-BAGP-2025 | U48: 2026-09-10 23:00:00 | V48: 2025: total exacto de BAGP; nota de prensa redondea a 29.419 GWh.
A49: R0000052 | B49: 2025-01-01 | C49: 2025-12-31 | D49: year | E49: PY_LOAD_FACTOR | F49: PY_SIN | G49: PY | H49: PY | I49: 63.6 | J49: percent | K49: 63.6 | L49: percent | M49: ANDE | N49: OFFICIAL_PRIMARY | O49: OFFICIAL_AGGREGATE | P49: 1 | Q49: 50 | R49: https://www.ande.gov.py/finanzas/BAGP%202025%20ANDE.pdf | S49: ANDE-BAGP-2025 | U49: 2026-09-10 23:00:00 | V49: Factor de carga publicado.
A50: R0000053 | B50: 2020-01-01 | C50: 2020-12-31 | D50: year | E50: PY_REGION_ENERGY | F50: PY_REGION_METROPOLITANO | G50: PY | H50: PY | I50: 9312851 | J50: MWh | K50: 9312851 | L50: MWh | M50: ANDE | N50: OFFICIAL_PRIMARY | O50: OFFICIAL_AGGREGATE | P50: 1 | Q50: 50 | R50: https://www.ande.gov.py/finanzas/ANDE%20-%20Resumen%20Estad%C3%ADstico%202020%20-%202024.pdf | S50: ANDE-STAT-2020-2024 | U50: 2026-09-10 23:00:00 | V50: Sistema/region: Metropolitano.
A51: R0000054 | B51: 2021-01-01 | C51: 2021-12-31 | D51: year | E51: PY_REGION_ENERGY | F51: PY_REGION_METROPOLITANO | G51: PY | H51: PY | I51: 9543744 | J51: MWh | K51: 9543744 | L51: MWh | M51: ANDE | N51: OFFICIAL_PRIMARY | O51: OFFICIAL_AGGREGATE | P51: 1 | Q51: 50 | R51: https://www.ande.gov.py/finanzas/ANDE%20-%20Resumen%20Estad%C3%ADstico%202020%20-%202024.pdf | S51: ANDE-STAT-2020-2024 | U51: 2026-09-10 23:00:00 | V51: Sistema/region: Metropolitano.
A52: R0000055 | B52: 2022-01-01 | C52: 2022-12-31 | D52: year | E52: PY_REGION_ENERGY | F52: PY_REGION_METROPOLITANO | G52: PY | H52: PY | I52: 9964357 | J52: MWh | K52: 9964357 | L52: MWh | M52: ANDE | N52: OFFICIAL_PRIMARY | O52: OFFICIAL_AGGREGATE | P52: 1 | Q52: 50 | R52: https://www.ande.gov.py/finanzas/ANDE%20-%20Resumen%20Estad%C3%ADstico%202020%20-%202024.pdf | S52: ANDE-STAT-2020-2024 | U52: 2026-09-10 23:00:00 | V52: Sistema/region: Metropolitano.
A53: R0000056 | B53: 2023-01-01 | C53: 2023-12-31 | D53: year | E53: PY_REGION_ENERGY | F53: PY_REGION_METROPOLITANO | G53: PY | H53: PY | I53: 11174060 | J53: MWh | K53: 11174060 | L53: MWh | M53: ANDE | N53: OFFICIAL_PRIMARY | O53: OFFICIAL_AGGREGATE | P53: 1 | Q53: 50 | R53: https://www.ande.gov.py/finanzas/ANDE%20-%20Resumen%20Estad%C3%ADstico%202020%20-%202024.pdf | S53: ANDE-STAT-2020-2024 | U53: 2026-09-10 23:00:00 | V53: Sistema/region: Metropolitano.
A54: R0000057 | B54: 2024-01-01 | C54: 2024-12-31 | D54: year | E54: PY_REGION_ENERGY | F54: PY_REGION_METROPOLITANO | G54: PY | H54: PY | I54: 12291090 | J54: MWh | K54: 12291090 | L54: MWh | M54: ANDE | N54: OFFICIAL_PRIMARY | O54: OFFICIAL_AGGREGATE | P54: 1 | Q54: 50 | R54: https://www.ande.gov.py/finanzas/ANDE%20-%20Resumen%20Estad%C3%ADstico%202020%20-%202024.pdf | S54: ANDE-STAT-2020-2024 | U54: 2026-09-10 23:00:00 | V54: Sistema/region: Metropolitano.
A55: R0000058 | B55: 2020-01-01 | C55: 2020-12-31 | D55: year | E55: PY_REGION_ENERGY | F55: PY_REGION_CENTRAL | G55: PY | H55: PY | I55: 1833781 | J55: MWh | K55: 1833781 | L55: MWh | M55: ANDE | N55: OFFICIAL_PRIMARY | O55: OFFICIAL_AGGREGATE | P55: 1 | Q55: 50 | R55: https://www.ande.gov.py/finanzas/ANDE%20-%20Resumen%20Estad%C3%ADstico%202020%20-%202024.pdf | S55: ANDE-STAT-2020-2024 | U55: 2026-09-10 23:00:00 | V55: Sistema/region: Central.
A56: R0000059 | B56: 2021-01-01 | C56: 2021-12-31 | D56: year | E56: PY_REGION_ENERGY | F56: PY_REGION_CENTRAL | G56: PY | H56: PY | I56: 1985053 | J56: MWh | K56: 1985053 | L56: MWh | M56: ANDE | N56: OFFICIAL_PRIMARY | O56: OFFICIAL_AGGREGATE | P56: 1 | Q56: 50 | R56: https://www.ande.gov.py/finanzas/ANDE%20-%20Resumen%20Estad%C3%ADstico%202020%20-%202024.pdf | S56: ANDE-STAT-2020-2024 | U56: 2026-09-10 23:00:00 | V56: Sistema/region: Central.
A57: R0000060 | B57: 2022-01-01 | C57: 2022-12-31 | D57: year | E57: PY_REGION_ENERGY | F57: PY_REGION_CENTRAL | G57: PY | H57: PY | I57: 2373625 | J57: MWh | K57: 2373625 | L57: MWh | M57: ANDE | N57: OFFICIAL_PRIMARY | O57: OFFICIAL_AGGREGATE | P57: 1 | Q57: 50 | R57: https://www.ande.gov.py/finanzas/ANDE%20-%20Resumen%20Estad%C3%ADstico%202020%20-%202024.pdf | S57: ANDE-STAT-2020-2024 | U57: 2026-09-10 23:00:00 | V57: Sistema/region: Central.
... A137: R0000141 | B137: 2026-01-01 | C137: 2026-05-31 | D137: period | E137: PY_CONSUMPTION_ENERGY_YTD | F137: PY_SIN | G137: PY | H137: PY | I137: 14587100 | J137: MWh | K137: 14587100 | L137: MWh | M137: ANDE | N137: OFFICIAL_PRIMARY | O137: OFFICIAL_AGGREGATE | P137: 1 | Q137: 50 | R137: https://www.ande.gov.py/interna.php?id=15361 | S137: ANDE-MAY-2026 | U137: 2026-09-10 23:00:00 | V137: Acumulado enero-mayo publicado por ANDE.
A138: R0000142 | B138: 2025-08-14 06:23:00 | C138: 2025-08-14 06:23:00 | D138: event | E138: PY_DEMAND | F138: PY_SIN | G138: PY | H138: PY | I138: 3070 | J138: MW | K138: 3070 | L138: MW | M138: ANDE | N138: OFFICIAL_PRIMARY | O138: OFFICIAL_MEASURED | P138: 1 | Q138: 50 | R138: https://www.ande.gov.py/interna.php?id=14173 | U138: 2026-09-10 23:00:00 | V138: Evento: Avería en interruptor 220 kV de Acaray; demanda reportada al momento del inconveniente. ANDE indica abastecimiento principalmente por Itaipú; no desglosa MW por central.
A139: R0000143 | B139: 2025-12-15 14:12:00 | C139: 2025-12-15 14:12:00 | D139: event | E139: PY_DEMAND | F139: PY_SIN | G139: PY | H139: PY | I139: 5280 | J139: MW | K139: 5280 | L139: MW | M139: ANDE | N139: OFFICIAL_PRIMARY | O139: OFFICIAL_MEASURED | P139: 1 | Q139: 50 | R139: https://www.ande.gov.py/interna.php?id=14816 | U139: 2026-09-10 23:00:00 | V139: Récord: Nuevo récord histórico de demanda instantánea 2025. La suma de aportes + exportación puede diferir conceptualmente de demanda según convención de signo/medición.
A140: R0000144 | B140: 2025-12-15 14:12:00 | C140: 2025-12-15 14:12:00 | D140: event | E140: POWER_TO_PY | F140: ITAIPU | G140: ITAIPU | H140: PY | I140: 3745 | J140: MW | K140: 3745 | L140: MW | M140: ANDE | N140: OFFICIAL_PRIMARY | O140: OFFICIAL_MEASURED | P140: 1 | Q140: 50 | R140: https://www.ande.gov.py/interna.php?id=14816 | U140: 2026-09-10 23:00:00 | V140: Récord: Nuevo récord histórico de demanda instantánea 2025. La suma de aportes + exportación puede diferir conceptualmente de demanda según convención de signo/medición.
A141: R0000145 | B141: 2025-12-15 14:12:00 | C141: 2025-12-15 14:12:00 | D141: event | E141: POWER_TO_PY | F141: YACYRETA | G141: YACYRETA | H141: PY | I141: 1419 | J141: MW | K141: 1419 | L141: MW | M141: ANDE | N141: OFFICIAL_PRIMARY | O141: OFFICIAL_MEASURED | P141: 1 | Q141: 50 | R141: https://www.ande.gov.py/interna.php?id=14816 | U141: 2026-09-10 23:00:00 | V141: Récord: Nuevo récord histórico de demanda instantánea 2025. La suma de aportes + exportación puede diferir conceptualmente de demanda según convención de signo/medición.
...

Sheet Prices
A1: price_id | B1: period_start | C1: period_end | D1: grain | E1: price_code | F1: asset_code | G1: market_counterparty | H1: value | I1: unit | J1: currency | K1: source_code | L1: authority_class | M1: quality_class | N1: source_url | O1: revision_priority | P1: notes
A2: P00001 | B2: 1990-01-01 | C2: 1990-12-31 | D2: year | E2: ANDE_TARIFF_RESIDENTIAL | F2: PY_SIN | G2: PY | H2: 56.1 | I2: Gs/kWh | J2: PYG | K2: ANDE | L2: OFFICIAL_PRIMARY | M2: OFFICIAL_AGGREGATE | N2: https://www.ande.gov.py/documentos_contables/157/compilacion_estadistica_1990-2010.pdf | O2: 75 | P2: Tarifa media anual sin impuestos segun compilacion.
A3: P00002 | B3: 1991-01-01 | C3: 1991-12-31 | D3: year | E3: ANDE_TARIFF_RESIDENTIAL | F3: PY_SIN | G3: PY | H3: 66.2 | I3: Gs/kWh | J3: PYG | K3: ANDE | L3: OFFICIAL_PRIMARY | M3: OFFICIAL_AGGREGATE | N3: https://www.ande.gov.py/documentos_contables/157/compilacion_estadistica_1990-2010.pdf | O3: 75 | P3: Tarifa media anual sin impuestos segun compilacion.
A4: P00003 | B4: 1992-01-01 | C4: 1992-12-31 | D4: year | E4: ANDE_TARIFF_RESIDENTIAL | F4: PY_SIN | G4: PY | H4: 66.3 | I4: Gs/kWh | J4: PYG | K4: ANDE | L4: OFFICIAL_PRIMARY | M4: OFFICIAL_AGGREGATE | N4: https://www.ande.gov.py/documentos_contables/157/compilacion_estadistica_1990-2010.pdf | O4: 75 | P4: Tarifa media anual sin impuestos segun compilacion.
A5: P00004 | B5: 1993-01-01 | C5: 1993-12-31 | D5: year | E5: ANDE_TARIFF_RESIDENTIAL | F5: PY_SIN | G5: PY | H5: 70.6 | I5: Gs/kWh | J5: PYG | K5: ANDE | L5: OFFICIAL_PRIMARY | M5: OFFICIAL_AGGREGATE | N5: https://www.ande.gov.py/documentos_contables/157/compilacion_estadistica_1990-2010.pdf | O5: 75 | P5: Tarifa media anual sin impuestos segun compilacion.
A6: P00005 | B6: 1994-01-01 | C6: 1994-12-31 | D6: year | E6: ANDE_TARIFF_RESIDENTIAL | F6: PY_SIN | G6: PY | H6: 85.5 | I6: Gs/kWh | J6: PYG | K6: ANDE | L6: OFFICIAL_PRIMARY | M6: OFFICIAL_AGGREGATE | N6: https://www.ande.gov.py/documentos_contables/157/compilacion_estadistica_1990-2010.pdf | O6: 75 | P6: Tarifa media anual sin impuestos segun compilacion.
A7: P00006 | B7: 1995-01-01 | C7: 1995-12-31 | D7: year | E7: ANDE_TARIFF_RESIDENTIAL | F7: PY_SIN | G7: PY | H7: 95.5 | I7: Gs/kWh | J7: PYG | K7: ANDE | L7: OFFICIAL_PRIMARY | M7: OFFICIAL_AGGREGATE | N7: https://www.ande.gov.py/documentos_contables/157/compilacion_estadistica_1990-2010.pdf | O7: 75 | P7: Tarifa media anual sin impuestos segun compilacion.
A8: P00007 | B8: 1996-01-01 | C8: 1996-12-31 | D8: year | E8: ANDE_TARIFF_RESIDENTIAL | F8: PY_SIN | G8: PY | H8: 118 | I8: Gs/kWh | J8: PYG | K8: ANDE | L8: OFFICIAL_PRIMARY | M8: OFFICIAL_AGGREGATE | N8: https://www.ande.gov.py/documentos_contables/157/compilacion_estadistica_1990-2010.pdf | O8: 75 | P8: Tarifa media anual sin impuestos segun compilacion.
A9: P00008 | B9: 1997-01-01 | C9: 1997-12-31 | D9: year | E9: ANDE_TARIFF_RESIDENTIAL | F9: PY_SIN | G9: PY | H9: 135.1 | I9: Gs/kWh | J9: PYG | K9: ANDE | L9: OFFICIAL_PRIMARY | M9: OFFICIAL_AGGREGATE | N9: https://www.ande.gov.py/documentos_contables/157/compilacion_estadistica_1990-2010.pdf | O9: 75 | P9: Tarifa media anual sin impuestos segun compilacion.
A10: P00009 | B10: 1998-01-01 | C10: 1998-12-31 | D10: year | E10: ANDE_TARIFF_RESIDENTIAL | F10: PY_SIN | G10: PY | H10: 159.9 | I10: Gs/kWh | J10: PYG | K10: ANDE | L10: OFFICIAL_PRIMARY | M10: OFFICIAL_AGGREGATE | N10: https://www.ande.gov.py/documentos_contables/157/compilacion_estadistica_1990-2010.pdf | O10: 75 | P10: Tarifa media anual sin impuestos segun compilacion.
A11: P00010 | B11: 1999-01-01 | C11: 1999-12-31 | D11: year | E11: ANDE_TARIFF_RESIDENTIAL | F11: PY_SIN | G11: PY | H11: 161.7 | I11: Gs/kWh | J11: PYG | K11: ANDE | L11: OFFICIAL_PRIMARY | M11: OFFICIAL_AGGREGATE | N11: https://www.ande.gov.py/documentos_contables/157/compilacion_estadistica_1990-2010.pdf | O11: 75 | P11: Tarifa media anual sin impuestos segun compilacion.
A12: P00011 | B12: 2000-01-01 | C12: 2000-12-31 | D12: year | E12: ANDE_TARIFF_RESIDENTIAL | F12: PY_SIN | G12: PY | H12: 171.4 | I12: Gs/kWh | J12: PYG | K12: ANDE | L12: OFFICIAL_PRIMARY | M12: OFFICIAL_AGGREGATE | N12: https://www.ande.gov.py/documentos_contables/157/compilacion_estadistica_1990-2010.pdf | O12: 75 | P12: Tarifa media anual sin impuestos segun compilacion.
A13: P00012 | B13: 2001-01-01 | C13: 2001-12-31 | D13: year | E13: ANDE_TARIFF_RESIDENTIAL | F13: PY_SIN | G13: PY | H13: 232 | I13: Gs/kWh | J13: PYG | K13: ANDE | L13: OFFICIAL_PRIMARY | M13: OFFICIAL_AGGREGATE | N13: https://www.ande.gov.py/documentos_contables/157/compilacion_estadistica_1990-2010.pdf | O13: 75 | P13: Tarifa media anual sin impuestos segun compilacion.
... A369: P00368 | B369: 2024-01-01 | C369: 2024-12-31 | D369: year | E369: ANDE_TARIFF_GENERAL_AVG | F369: PY_SIN | G369: PY | H369: 374.6 | I369: Gs/kWh | J369: PYG | K369: ANDE | L369: OFFICIAL_PRIMARY | M369: OFFICIAL_AGGREGATE | N369: https://www.ande.gov.py/finanzas/ANDE%20-%20Resumen%20Estad%C3%ADstico%202020%20-%202024.pdf | O369: 95 | P369: Tarifa media anual segun Resumen Estadistico 2020-2024. Fuente mas reciente para este periodo; preservar revisiones previas para auditoria.

Sheet Retail_Tariff_History
A1: Año | B1: Residencial media (Gs/kWh) | C1: Nacional media (Gs/kWh) | D1: Exportación ANDE media (Gs/kWh) | E1: Var. residencial YoY | F1: Residencial / Exportación | G1: Calidad | H1: Fuente principal
A2: 1990 | B2: 56.1 | C2: 52.2 | D2: 44.5 | F2: =IFERROR(B2/D2,"") | G2: OFICIAL | H2: https://www.ande.gov.py/documentos_contables/157/compilacion_estadistica_1990-2010.pdf
A3: 1991 | B3: 66.2 | C3: 62.2 | D3: 44.6 | E3: =IFERROR(B3/B2-1,"") | F3: =IFERROR(B3/D3,"") | G3: OFICIAL | H3: https://www.ande.gov.py/documentos_contables/157/compilacion_estadistica_1990-2010.pdf
A4: 1992 | B4: 66.3 | C4: 61.7 | D4: 50.2 | E4: =IFERROR(B4/B3-1,"") | F4: =IFERROR(B4/D4,"") | G4: OFICIAL | H4: https://www.ande.gov.py/documentos_contables/157/compilacion_estadistica_1990-2010.pdf
A5: 1993 | B5: 70.6 | C5: 66.4 | D5: 65.9 | E5: =IFERROR(B5/B4-1,"") | F5: =IFERROR(B5/D5,"") | G5: OFICIAL | H5: https://www.ande.gov.py/documentos_contables/157/compilacion_estadistica_1990-2010.pdf
A6: 1994 | B6: 85.5 | C6: 80.3 | D6: 66.2 | E6: =IFERROR(B6/B5-1,"") | F6: =IFERROR(B6/D6,"") | G6: OFICIAL | H6: https://www.ande.gov.py/documentos_contables/157/compilacion_estadistica_1990-2010.pdf
A7: 1995 | B7: 95.5 | C7: 89.2 | D7: 78.7 | E7: =IFERROR(B7/B6-1,"") | F7: =IFERROR(B7/D7,"") | G7: OFICIAL | H7: https://www.ande.gov.py/documentos_contables/157/compilacion_estadistica_1990-2010.pdf
A8: 1996 | B8: 118 | C8: 110 | D8: 75.4 | E8: =IFERROR(B8/B7-1,"") | F8: =IFERROR(B8/D8,"") | G8: OFICIAL | H8: https://www.ande.gov.py/documentos_contables/157/compilacion_estadistica_1990-2010.pdf
A9: 1997 | B9: 135.1 | C9: 124.6 | D9: 55 | E9: =IFERROR(B9/B8-1,"") | F9: =IFERROR(B9/D9,"") | G9: OFICIAL | H9: https://www.ande.gov.py/documentos_contables/157/compilacion_estadistica_1990-2010.pdf
A10: 1998 | B10: 159.9 | C10: 148.6 | D10: 48.7 | E10: =IFERROR(B10/B9-1,"") | F10: =IFERROR(B10/D10,"") | G10: OFICIAL | H10: https://www.ande.gov.py/documentos_contables/157/compilacion_estadistica_1990-2010.pdf
A11: 1999 | B11: 161.7 | C11: 146.8 | D11: 40.2 | E11: =IFERROR(B11/B10-1,"") | F11: =IFERROR(B11/D11,"") | G11: OFICIAL | H11: https://www.ande.gov.py/documentos_contables/157/compilacion_estadistica_1990-2010.pdf
A12: 2000 | B12: 171.4 | C12: 159.1 | D12: 53.7 | E12: =IFERROR(B12/B11-1,"") | F12: =IFERROR(B12/D12,"") | G12: OFICIAL | H12: https://www.ande.gov.py/documentos_contables/157/compilacion_estadistica_1990-2010.pdf
A13: 2001 | B13: 232 | C13: 211.2 | D13: 60.9 | E13: =IFERROR(B13/B12-1,"") | F13: =IFERROR(B13/D13,"") | G13: OFICIAL | H13: https://www.ande.gov.py/documentos_contables/157/compilacion_estadistica_1990-2010.pdf
A14: 2002 | B14: 299.7 | C14: 275.4 | D14: 51.3 | E14: =IFERROR(B14/B13-1,"") | F14: =IFERROR(B14/D14,"") | G14: OFICIAL | H14: https://www.ande.gov.py/documentos_contables/157/compilacion_estadistica_1990-2010.pdf
... A36: 2024 | B36: 415.5 | C36: 371.9 | D36: 899.3 | E36: =IFERROR(B36/B35-1,"") | F36: =IFERROR(B36/D36,"") | G36: OFICIAL | H36: https://www.ande.gov.py/finanzas/ANDE%20-%20Resumen%20Estad%C3%ADstico%202020%20-%202024.pdf

Sheet Retail_Tariff_Current
A1: ANDE — Tarifas residenciales vigentes de referencia
A2: Vigencia de referencia | B2: 27-11-2024 → vigente en portal ANDE consultado 2026
A4: Categoría | B4: Nombre | C4: Desde kWh/mes | D4: Hasta kWh/mes | E4: Precio nominal | F4: Unidad | G4: Tipo | H4: Fuente
A5: 142 | B5: Residencial normal BT | C5: 0 | D5: 50 | E5: 311.55 | F5: Gs/kWh | G5: Tarifa residencial normal | H5: https://www.ande.gov.py/docs/tarifas/Pliego%20de%20Tarifas%20NRO%2021%20Version%20Actualizada%2027-11-2024.pdf
A6: 142 | B6: Residencial normal BT | C6: 51 | D6: 150 | E6: 349.89 | F6: Gs/kWh | G6: Tarifa residencial normal | H6: https://www.ande.gov.py/docs/tarifas/Pliego%20de%20Tarifas%20NRO%2021%20Version%20Actualizada%2027-11-2024.pdf
A7: 142 | B7: Residencial normal BT | C7: 151 | D7: 300 | E7: 365.45 | F7: Gs/kWh | G7: Tarifa residencial normal | H7: https://www.ande.gov.py/docs/tarifas/Pliego%20de%20Tarifas%20NRO%2021%20Version%20Actualizada%2027-11-2024.pdf
